Workbook

Sheet Lead Log
A1: Week Of | B1: Date | C1: Lead Name | D1: Phone | E1: Company | F1: Prospect Type | G1: Source of Lead | H1: Campaign | I1: Lead ID | J1: Source of Referral | K1: Responded? | L1: Qualified? | M1: Reason Not Qualified | N1: Next Follow-up | O1: Notes
A2: =IF(B2="","",TEXT(B2-(WEEKDAY(B2,2)-1),"mmm d")&" - "&TEXT(B2-(WEEKDAY(B2,2)-1)+5,"mmm d")) -> Jul 6 - Jul 11 | B2: 46209 | C2: Pravine | F2: Investor | K2: Yes | O2: Contact method: Phone Call | Attempts: 3
A3: =IF(B3="","",TEXT(B3-(WEEKDAY(B3,2)-1),"mmm d")&" - "&TEXT(B3-(WEEKDAY(B3,2)-1)+5,"mmm d")) -> Jul 6 - Jul 11 | B3: 46209 | C3: Vikas Bedi | F3: Investor | K3: Yes | O3: Contact method: Phone Call | Attempts: 2
A4: =IF(B4="","",TEXT(B4-(WEEKDAY(B4,2)-1),"mmm d")&" - "&TEXT(B4-(WEEKDAY(B4,2)-1)+5,"mmm d")) -> Jul 6 - Jul 11 | B4: 46209 | C4: Pam Paolo | F4: Investor | K4: Yes | O4: Contact method: Phone Call | Attempts: 1
A5: =IF(B5="","",TEXT(B5-(WEEKDAY(B5,2)-1),"mmm d")&" - "&TEXT(B5-(WEEKDAY(B5,2)-1)+5,"mmm d")) -> Jul 6 - Jul 11 | B5: 46210 | C5: Dan Talos | F5: Developer | K5: Yes | O5: Contact method: Other | Attempts: 2
A6: =IF(B6="","",TEXT(B6-(WEEKDAY(B6,2)-1),"mmm d")&" - "&TEXT(B6-(WEEKDAY(B6,2)-1)+5,"mmm d")) -> Jul 6 - Jul 11 | B6: 46211 | C6: Frédéric Louis | F6: Investor | K6: Yes | O6: Contact method: Phone Call | Attempts: 3 | Follow-up (as written): N/A | Dead end
A7: =IF(B7="","",TEXT(B7-(WEEKDAY(B7,2)-1),"mmm d")&" - "&TEXT(B7-(WEEKDAY(B7,2)-1)+5,"mmm d")) -> Jul 6 - Jul 11 | B7: 46211 | C7: Nino Saad | F7: Investor | K7: Yes | O7: Contact method: Phone Call | Attempts: 2
A8: =IF(B8="","",TEXT(B8-(WEEKDAY(B8,2)-1),"mmm d")&" - "&TEXT(B8-(WEEKDAY(B8,2)-1)+5,"mmm d")) -> Jul 6 - Jul 11 | B8: 46211 | C8: Suzanne Kouahou | F8: Other | K8: Yes | O8: Contact method: Phone Call | Attempts: 1 | Follow-up (as written): N/A | Dead end
A9: =IF(B9="","",TEXT(B9-(WEEKDAY(B9,2)-1),"mmm d")&" - "&TEXT(B9-(WEEKDAY(B9,2)-1)+5,"mmm d")) -> Jul 6 - Jul 11 | B9: 46211 | C9: Fabrice Kamdem | F9: Developer | K9: Yes | O9: Contact method: Email | Attempts: 7 | Follow-up (as written): July 9th | Unreachable, line is not connected.
A10: =IF(B10="","",TEXT(B10-(WEEKDAY(B10,2)-1),"mmm d")&" - "&TEXT(B10-(WEEKDAY(B10,2)-1)+5,"mmm d")) -> Jul 6 - Jul 11 | B10: 46211 | C10: Vince Adams | F10: Investor | K10: No | O10: Contact method: Email | Attempts: 3 | email, phonecall, text
A11: =IF(B11="","",TEXT(B11-(WEEKDAY(B11,2)-1),"mmm d")&" - "&TEXT(B11-(WEEKDAY(B11,2)-1)+5,"mmm d")) -> Jul 6 - Jul 11 | B11: 46211 | C11: Michael Stavrou | F11: Developer | K11: Yes | O11: Contact method: Phone Call | Attempts: 3
A12: =IF(B12="","",TEXT(B12-(WEEKDAY(B12,2)-1),"mmm d")&" - "&TEXT(B12-(WEEKDAY(B12,2)-1)+5,"mmm d")) -> Jul 6 - Jul 11 | B12: 46211 | C12: Rannie Dangle | F12: Investor | K12: No | O12: Contact method: Email | Attempts: 4
A13: =IF(B13="","",TEXT(B13-(WEEKDAY(B13,2)-1),"mmm d")&" - "&TEXT(B13-(WEEKDAY(B13,2)-1)+5,"mmm d")) -> Jul 6 - Jul 11 | B13: 46211 | C13: Leonardo Montes | F13: Investor | K13: Yes | O13: Contact method: Phone Call | Attempts: 3
... A18: =IF(B18="","",TEXT(B18-(WEEKDAY(B18,2)-1),"mmm d")&" - "&TEXT(B18-(WEEKDAY(B18,2)-1)+5,"mmm d")) -> Jul 6 - Jul 11 | B18: 46211 | C18: Steve Dunne | F18: Investor | K18: Yes | O18: Contact method: Email | Attempts: 1 | Follow-up (as written): July 13th | Will need to be a meeting in Halifax.
A19: =IF(B19="","",TEXT(B19-(WEEKDAY(B19,2)-1),"mmm d")&" - "&TEXT(B19-(WEEKDAY(B19,2)-1)+5,"mmm d")) -> Jul 6 - Jul 11 | B19: 46212 | C19: Pierre-Alexandre Rochefort | E19: Rochefort | F19: Other | K19: Yes | O19: Contact method: In-Person | Attempts: 1
A20: =IF(B20="","",TEXT(B20-(WEEKDAY(B20,2)-1),"mmm d")&" - "&TEXT(B20-(WEEKDAY(B20,2)-1)+5,"mmm d")) -> Jul 6 - Jul 11 | B20: 46212 | C20: Sarah Belouchi | E20: PFD | F20: Lawyer | K20: Yes | O20: Contact method: In-Person | Attempts: 1
A21: =IF(B21="","",TEXT(B21-(WEEKDAY(B21,2)-1),"mmm d")&" - "&TEXT(B21-(WEEKDAY(B21,2)-1)+5,"mmm d")) -> Jul 6 - Jul 11 | B21: 46212 | C21: Louis-Philippe Desjardins | E21: PFD | F21: Lawyer | K21: Yes | O21: Contact method: In-Person | Attempts: 1
A22: =IF(B22="","",TEXT(B22-(WEEKDAY(B22,2)-1),"mmm d")&" - "&TEXT(B22-(WEEKDAY(B22,2)-1)+5,"mmm d")) -> Jul 6 - Jul 11 | B22: 46212 | C22: Alexandra Darras | E22: BDC | F22: Banker | K22: Yes | O22: Contact method: In-Person | Attempts: 1
A23: =IF(B23="","",TEXT(B23-(WEEKDAY(B23,2)-1),"mmm d")&" - "&TEXT(B23-(WEEKDAY(B23,2)-1)+5,"mmm d")) -> Jul 6 - Jul 11 | B23: 46212 | C23: Alexia Deshaies | E23: BNC | F23: Banker | K23: Yes | O23: Contact method: In-Person | Attempts: 1
A24: =IF(B24="","",TEXT(B24-(WEEKDAY(B24,2)-1),"mmm d")&" - "&TEXT(B24-(WEEKDAY(B24,2)-1)+5,"mmm d")) -> Jul 6 - Jul 11 | B24: 46212 | C24: Renaud Mondor | E24: BNC | F24: Banker | K24: Yes | O24: Contact method: LinkedIn | Attempts: 1
A25: =IF(B25="","",TEXT(B25-(WEEKDAY(B25,2)-1),"mmm d")&" - "&TEXT(B25-(WEEKDAY(B25,2)-1)+5,"mmm d")) -> Jul 6 - Jul 11 | B25: 46212 | C25: David Stefani | E25: TD | F25: Banker | K25: Yes | O25: Contact method: LinkedIn | Attempts: 1
A26: =IF(B26="","",TEXT(B26-(WEEKDAY(B26,2)-1),"mmm d")&" - "&TEXT(B26-(WEEKDAY(B26,2)-1)+5,"mmm d")) -> Jul 6 - Jul 11 | B26: 46212 | C26: Daphne Pungartnik | E26: Royal Lepage | F26: Other | K26: Yes | O26: Contact method: LinkedIn | Attempts: 1
A27: =IF(B27="","",TEXT(B27-(WEEKDAY(B27,2)-1),"mmm d")&" - "&TEXT(B27-(WEEKDAY(B27,2)-1)+5,"mmm d")) -> Jul 6 - Jul 11 | B27: 46212 | C27: Elisabeth Cabrera | E27: TD | F27: Banker | K27: Yes | O27: Contact method: LinkedIn | Attempts: 1
A28: =IF(B28="","",TEXT(B28-(WEEKDAY(B28,2)-1),"mmm d")&" - "&TEXT(B28-(WEEKDAY(B28,2)-1)+5,"mmm d")) -> Jul 6 - Jul 11 | B28: 46212 | C28: Clifton Mahotieres | E28: Medical professional | F28: Other | K28: Yes | O28: Contact method: LinkedIn | Attempts: 1
A29: =IF(B29="","",TEXT(B29-(WEEKDAY(B29,2)-1),"mmm d")&" - "&TEXT(B29-(WEEKDAY(B29,2)-1)+5,"mmm d")) -> Jul 6 - Jul 11 | B29: 46212 | C29: Amélie Beauchamp | E29: Desjardins | F29: Other | K29: Yes | O29: Contact method: In-Person | Attempts: 1
A30: =IF(B30="","",TEXT(B30-(WEEKDAY(B30,2)-1),"mmm d")&" - "&TEXT(B30-(WEEKDAY(B30,2)-1)+5,"mmm d")) -> Jul 6 - Jul 11 | B30: 46212 | C30: Anthony Lorrain | E30: BNC | F30: Other | K30: Yes | O30: Contact method: In-Person | Attempts: 1
A31: =IF(B31="","",TEXT(B31-(WEEKDAY(B31,2)-1),"mmm d")&" - "&TEXT(B31-(WEEKDAY(B31,2)-1)+5,"mmm d")) -> Jul 6 - Jul 11 | B31: 46212 | C31: Antoine Niquette-Serrechia | F31: Other | K31: Yes | O31: Contact method: In-Person | Attempts: 1
A32: =IF(B32="","",TEXT(B32-(WEEKDAY(B32,2)-1),"mmm d")&" - "&TEXT(B32-(WEEKDAY(B32,2)-1)+5,"mmm d")) -> Jul 6 - Jul 11 | B32: 46212 | C32: Audrey Bélanger | E32: Les Batisseurs | F32: Accountant | K32: Yes | O32: Contact method: LinkedIn | Attempts: 1
A33: =IF(B33="","",TEXT(B33-(WEEKDAY(B33,2)-1),"mmm d")&" - "&TEXT(B33-(WEEKDAY(B33,2)-1)+5,"mmm d")) -> Jul 6 - Jul 11 | B33: 46212 | C33: Charles-Étienne Pressé | E33: Groupe CH | F33: Lawyer | K33: Yes | O33: Contact method: LinkedIn | Attempts: 1
A34: =IF(B34="","",TEXT(B34-(WEEKDAY(B34,2)-1),"mmm d")&" - "&TEXT(B34-(WEEKDAY(B34,2)-1)+5,"mmm d")) -> Jul 6 - Jul 11 | B34: 46212 | C34: Emmanuelle Alcindor | F34: Other | K34: Yes | O34: Contact method: In-Person | Attempts: 1
A35: =IF(B35="","",TEXT(B35-(WEEKDAY(B35,2)-1),"mmm d")&" - "&TEXT(B35-(WEEKDAY(B35,2)-1)+5,"mmm d")) -> Jul 6 - Jul 11 | B35: 46212 | C35: Etienne C. Laplante | E35: Les Batisseurs | F35: Lawyer | K35: Yes | O35: Contact method: In-Person | Attempts: 1
A36: =IF(B36="","",TEXT(B36-(WEEKDAY(B36,2)-1),"mmm d")&" - "&TEXT(B36-(WEEKDAY(B36,2)-1)+5,"mmm d")) -> Jul 6 - Jul 11 | B36: 46212 | C36: Eve Provost | E36: BNC | F36: Banker | K36: Yes | O36: Contact method: In-Person | Attempts: 1
A37: =IF(B37="","",TEXT(B37-(WEEKDAY(B37,2)-1),"mmm d")&" - "&TEXT(B37-(WEEKDAY(B37,2)-1)+5,"mmm d")) -> Jul 6 - Jul 11 | B37: 46212 | C37: Francis Corriveau-Sauvé | F37: Accountant | K37: Yes | O37: Contact method: In-Person | Attempts: 1
A38: =IF(B38="","",TEXT(B38-(WEEKDAY(B38,2)-1),"mmm d")&" - "&TEXT(B38-(WEEKDAY(B38,2)-1)+5,"mmm d")) -> Jul 6 - Jul 11 | B38: 46212 | C38: Francis Gendron | E38: Desjardins | F38: Banker | K38: Yes | O38: Contact method: In-Person | Attempts: 1
A39: =IF(B39="","",TEXT(B39-(WEEKDAY(B39,2)-1),"mmm d")&" - "&TEXT(B39-(WEEKDAY(B39,2)-1)+5,"mmm d")) -> Jul 6 - Jul 11 | B39: 46212 | C39: Frederic Paquette-Perreault | F39: Other | K39: Yes | O39: Contact method: In-Person | Attempts: 1
A40: =IF(B40="","",TEXT(B40-(WEEKDAY(B40,2)-1),"mmm d")&" - "&TEXT(B40-(WEEKDAY(B40,2)-1)+5,"mmm d")) -> Jul 13 - Jul 18 | B40: 46220 | C40: Yacine Bouda | E40: PMML | F40: Real Estate Broker | K40: Yes | O40: Contact method: In-Person | Attempts: 1
A41: =IF(B41="","",TEXT(B41-(WEEKDAY(B41,2)-1),"mmm d")&" - "&TEXT(B41-(WEEKDAY(B41,2)-1)+5,"mmm d")) -> Jul 20 - Jul 25 | B41: 46223 | C41: Mike Jagger linkedin after in person | E41: Rosefellow | F41: Developer | K41: Yes | O41: Contact method: LinkedIn | Attempts: 1
A42: =IF(B42="","",TEXT(B42-(WEEKDAY(B42,2)-1),"mmm d")&" - "&TEXT(B42-(WEEKDAY(B42,2)-1)+5,"mmm d")) -> Jul 20 - Jul 25 | B42: 46223 | C42: Angelo Ghaleb | E42: Multi-Pret (residential) | F42: Other | K42: Yes | O42: Contact method: In-Person | Attempts: 1
A43: =IF(B43="","",TEXT(B43-(WEEKDAY(B43,2)-1),"mmm d")&" - "&TEXT(B43-(WEEKDAY(B43,2)-1)+5,"mmm d")) -> Jul 20 - Jul 25 | B43: 46229 | C43: Christopher Salador | E43: Remax | F43: Real Estate Broker | K43: Yes | O43: Contact method: In-Person | Attempts: 1
A44: =IF(B44="","",TEXT(B44-(WEEKDAY(B44,2)-1),"mmm d")&" - "&TEXT(B44-(WEEKDAY(B44,2)-1)+5,"mmm d")) -> Jul 20 - Jul 25 | B44: 46229 | C44: Maxime Belma | E44: Remax | F44: Real Estate Broker | K44: Yes | O44: Contact method: In-Person | Attempts: 1
...

Sheet Weekly Summary
A1: WEEKLY PIPELINE MEETING SUMMARY
A2: Weekly target (leads responded): | C2: 25
A4: Week Of | B4: Leads Contacted | C4: Responded | D4: Response Rate | E4: Target Met?
A5: Jul 6 - Jul 11 | B5: =COUNTIF('Lead Log'!$A:$A,A5) -> 38 | C5: =COUNTIFS('Lead Log'!$A:$A,A5,'Lead Log'!$K:$K,"Yes") -> 34 | D5: =IFERROR(C5/B5,0) -> 0.89473684 | E5: =IF(C5>=$C$2,"Yes","No") -> Yes
A6: Jul 13 - Jul 18 | B6: =COUNTIF('Lead Log'!$A:$A,A6) -> 1 | C6: =COUNTIFS('Lead Log'!$A:$A,A6,'Lead Log'!$K:$K,"Yes") -> 1 | D6: =IFERROR(C6/B6,0) -> 1 | E6: =IF(C6>=$C$2,"Yes","No") -> No
A7: Jul 20 - Jul 25 | B7: =COUNTIF('Lead Log'!$A:$A,A7) -> 6 | C7: =COUNTIFS('Lead Log'!$A:$A,A7,'Lead Log'!$K:$K,"Yes") -> 6 | D7: =IFERROR(C7/B7,0) -> 1 | E7: =IF(C7>=$C$2,"Yes","No") -> No
A8: Jul 27 - Aug 1 | B8: =COUNTIF('Lead Log'!$A:$A,A8) -> 11 | C8: =COUNTIFS('Lead Log'!$A:$A,A8,'Lead Log'!$K:$K,"Yes") -> 6 | D8: =IFERROR(C8/B8,0) -> 0.54545455 | E8: =IF(C8>=$C$2,"Yes","No") -> No
A9: Aug 3 - Aug 8 | B9: =COUNTIF('Lead Log'!$A:$A,A9) -> 17 | C9: =COUNTIFS('Lead Log'!$A:$A,A9,'Lead Log'!$K:$K,"Yes") -> 16 | D9: =IFERROR(C9/B9,0) -> 0.94117647 | E9: =IF(C9>=$C$2,"Yes","No") -> No
A10: Aug 10 - Aug 15 | B10: =COUNTIF('Lead Log'!$A:$A,A10) -> 23 | C10: =COUNTIFS('Lead Log'!$A:$A,A10,'Lead Log'!$K:$K,"Yes") -> 20 | D10: =IFERROR(C10/B10,0) -> 0.86956522 | E10: =IF(C10>=$C$2,"Yes","No") -> No
A12: Add weeks by continuing the Mon-Sat pattern down — formulas recalculate automatically.
